Workbook
Name _Toc301930468: TestDesign!$B$219
Name _Toc301930478: TestDesign!$B$379
Name ACTION: #REF!
Name LOCAL_DATE_SEPARATOR: #REF!
Name LOCAL_DAY_FORMAT: #REF!
Name LOCAL_HOUR_FORMAT: #REF!
Name LOCAL_MINUTE_FORMAT: #REF!
Name LOCAL_MONTH_FORMAT: #REF!
Name LOCAL_SECOND_FORMAT: #REF!
Name LOCAL_TIME_SEPARATOR: #REF!
Name LOCAL_YEAR_FORMAT: #REF!

Sheet Cover
B2: TEST CASE
B4: Project Name | C4: KICAP | F4: Creator | G4: Nguyễn Trần Thanh Phong
B5: Project Code | C5: https://github.com/TuanHoangMinh12/Kiem_Thu_Nhom16 | F5: Reviewer/Approver
B6: Document Code | C6: =C5&"_TestCase_V0.1" -> https://github.com/TuanHoangMinh12/Kiem_Thu_Nhom16_TestCase_V0.1 | F6: Issue Date | G6: 46318
F7: Version | G7: 0.1
B10: Record of change
B11: Effective Date | C11: Version | D11: Change Item | E11: *A,D,M | F11: Change description | G11: Reference
B12: 46318 | C12: 0.1 | E12: A | F12: Tạo test case chức năng Shopping Cart (30 TC) | G12: Phong

Sheet Test case List
D1: TEST CASE LIST
B3: Project Name | D3: =Cover!C4 -> KICAP
B4: Project Code | D4: =Cover!C5 -> https://github.com/TuanHoangMinh12/Kiem_Thu_Nhom16
B5: Test Environment Setup Description | D5: 1. Website: https://kicap.vn (môi trường production, chỉ thao tác thêm giỏ/không đặt hàng thật) 2. Trình duyệt: Google Chrome bản mới nhất (kiểm tra chéo: Firefox, Edge) 3. Hệ điều hành: Windows 10/11; độ phân giải 1920x1080 (kiểm tra thêm mobile 390x844) 4. Dữ liệu test: SP_A = sản phẩm "Có sẵn" có >= 2 phiên bản (V1, V2); SP_B = sản phẩm "Có sẵn" khác; SP_C = sản phẩm "Hết hàng"; SP_D = sản phẩm "Pre-order"; SP_E = sản phẩm đang giảm giá 5. Tài khoản: không cần (test với vai trò khách). Đăng nhập/Đăng ký do thành viên khác phụ trách
B8: No | C8: Function Name | D8: Sheet Name | E8: Description | F8: Pre-Condition
B9: 1 | C9: Shopping Cart (Giỏ hàng) | D9: Shopping Cart | E9: Thêm sản phẩm vào giỏ, thay đổi số lượng, xóa sản phẩm, tính tiền, lưu giỏ, chuyển sang thanh toán | F9: Truy cập kicap.vn, chưa đăng nhập; có sản phẩm test SP_A..SP_E

Sheet TestDesign
A1: Requirement Level 1 | B1: Requirement Level 2 | C1: Requirement Level 3 | D1: Test Criteria | E1: Test Type | F1: Note
A2: 6.1 Giỏ hàng (Shopping Cart) | B2: Shopping Cart | C2: Displaying | D2: Giỏ hàng trống: mở /cart bằng biểu tượng giỏ -> [ShoppingCart-1] | E2: Function
D3: Layout trang giỏ hàng có sản phẩm -> [ShoppingCart-2] | E3: GUI
D4: Thông tin sản phẩm trong giỏ khớp trang chi tiết -> [ShoppingCart-3] | E4: Function
C5: Add to cart | D5: Thêm sản phẩm "Có sẵn" - popup xác nhận -> [ShoppingCart-4] | E5: Function
D6: Popup: nút [Tiếp tục mua hàng] -> [ShoppingCart-5] | E6: Function
D7: Popup: nút [Kiểm tra giỏ hàng] -> [ShoppingCart-6] | E7: Function
D8: Thêm đúng phiên bản được chọn -> [ShoppingCart-7] | E8: Function
D9: Thêm cùng sản phẩm + cùng phiên bản 2 lần (gộp dòng) -> [ShoppingCart-8] | E9: Function | F9: Equivalence partitioning
C10: Add Volunteering Opportunity | D10: Thêm cùng sản phẩm + khác phiên bản (tách dòng) -> [ShoppingCart-9] | E10: Function
D11: Thêm 2 sản phẩm khác nhau -> [ShoppingCart-10] | E11: Function
D12: Sản phẩm "Hết hàng" -> [ShoppingCart-11] | E12: Function | F12: Trạng thái sản phẩm
D13: Sản phẩm "Pre-order" -> [ShoppingCart-12] | E13: Function | F13: Trạng thái sản phẩm
D14: Thêm khi chưa đăng nhập (khách) -> [ShoppingCart-13] | E14: Function | F14: Login/Register do thành viên khác phụ trách
C15: Quantity | D15: Tăng số lượng bằng nút [+] -> [ShoppingCart-14] | E15: Function
D16: Giảm số lượng bằng nút [-] -> [ShoppingCart-15] | E16: Function
D17: Giảm khi số lượng = 1 (giá trị biên dưới) -> [ShoppingCart-16] | E17: Function | F17: Boundary value
D18: Nhập số lượng hợp lệ -> [ShoppingCart-17] | E18: Function
D19: Nhập 0 -> [ShoppingCart-18] | E19: Function | F19: Boundary value
D20: Nhập số âm -> [ShoppingCart-19] | E20: Function | F20: Invalid partition
C21: Amend Volunteering Opportunity | D21: Nhập ký tự chữ -> [ShoppingCart-20] | E21: Function | F21: Invalid partition
D22: Nhập số thập phân -> [ShoppingCart-21] | E22: Function | F22: Invalid partition
D23: Nhập số lượng vượt tồn kho -> [ShoppingCart-22] | E23: Function | F23: Boundary value
C24: Remove | D24: Xóa 1 sản phẩm khỏi giỏ nhiều sản phẩm -> [ShoppingCart-23] | E24: Function
D25: Xóa sản phẩm cuối cùng -> [ShoppingCart-24] | E25: Function
C26: Calculation | D26: Thành tiền/tổng tiền với sản phẩm giảm giá -> [ShoppingCart-25] | E26: Function
C27: Persistence | D27: Giữ giỏ sau khi tải lại trang -> [ShoppingCart-26] | E27: Function
C28: Mark In-active Volunteering Opportunity | D28: Giữ giỏ khi mở tab mới / mở lại trình duyệt -> [ShoppingCart-27] | E28: Function
D29: Số lượng ở biểu tượng giỏ đồng bộ -> [ShoppingCart-28] | E29: Function
B30: 6.5.7 Minor Work Projects | C30: Checkout | D30: Nút [Thanh toán] khi giỏ có sản phẩm -> [ShoppingCart-29] | E30: Function | F30: Chức năng Checkout do thành viên khác/ngoài phạm vi
D31: Truy cập thanh toán khi giỏ trống -> [ShoppingCart-30] | E31: Function

Sheet Shopping Cart
A2: Module Code | B2: ShoppingCart | J2: Passed
A3: Test requirement | B3: Shopping Cart (Giỏ hàng) | J3: Failed
A4: Tester | B4: Ho Ten (22130212) | J4: Blocked
A5: Passed | B5: Failed | C5: Untested | D5: Blocked | E5: Skipped | F5: Number of Test cases | J5: Untested
A6: =COUNTIF(F9:F996,"Passed") -> 0 | B6: =COUNTIF(F9:F996,"Failed") -> 0 | C6: =F6-E6-D6-B6-A6 -> 30 | D6: =COUNTIF(F$9:F$996,"Blocked") -> 0 | E6: =COUNTIF(F$9:F$996,"Skipped") -> 0 | F6: =COUNTA(A9:A996) -> 30 | J6: Skipped
A8: ID | B8: Test Case Description | C8: Test Case Procedure | D8: Expected Output | E8: Inter-test case Dependence | F8: Result | G8: Test date | H8: Note
A9: =IF(OR(B9<>"",D9<>""),"["&TEXT($B$2,"##")&"-"&TEXT(ROW()-8,"##")&"]","") -> [ShoppingCart-1] | B9: Kiểm tra mở trang giỏ hàng khi giỏ trống bằng biểu tượng giỏ ở header | C9: Pre-condition: + Dùng Chrome, truy cập https://kicap.vn, chưa đăng nhập (khách) + SP_A: sản phẩm "Có sẵn" có nhiều phiên bản; SP_B: sản phẩm "Có sẵn" khác + Giỏ hàng đang trống Step: 1. Quan sát biểu tượng giỏ hàng ở header 2. Click biểu tượng giỏ hàng | D9: 1. Biểu tượng giỏ hiển thị, không có số lượng (hoặc số 0) 2. Chuyển đến trang /cart - Hiển thị thông báo giỏ hàng trống - Không hiển thị nút [Thanh toán] hoạt động - Có liên kết/nút quay lại mua sắm | F9: Untested | H9: Cần đối chiếu nội dung thông báo giỏ trống trên site thật
A10: =IF(OR(B10<>"",D10<>""),"["&TEXT($B$2,"##")&"-"&TEXT(ROW()-8,"##")&"]","") -> [ShoppingCart-2] | B10: Kiểm tra giao diện (layout) trang giỏ hàng khi có sản phẩm | C10: Pre-condition: + Dùng Chrome, truy cập https://kicap.vn, chưa đăng nhập (khách) + SP_A: sản phẩm "Có sẵn" có nhiều phiên bản; SP_B: sản phẩm "Có sẵn" khác + Giỏ hàng đang trống Step: 1. Mở trang chi tiết SP_A, click [Thêm vào giỏ hàng] 2. Click [Kiểm tra giỏ hàng] 3. Quan sát bố cục trang /cart | D10: 1. Popup "Thêm vào giỏ hàng thành công" hiển thị 2. Chuyển đến /cart 3. Mỗi dòng hiển thị: ảnh, tên sản phẩm, phiên bản, đơn giá, số lượng, thành tiền, nút xóa; có phần tổng tiền và nút [Thanh toán]; căn chỉnh, font, màu thống nhất, không vỡ layout | F10: Untested | H10: Loại GUI
A11: =IF(OR(B11<>"",D11<>""),"["&TEXT($B$2,"##")&"-"&TEXT(ROW()-8,"##")&"]","") -> [ShoppingCart-3] | B11: Kiểm tra thông tin sản phẩm trong giỏ khớp với trang chi tiết | C11: Pre-condition: + Dùng Chrome, truy cập https://kicap.vn, chưa đăng nhập (khách) + SP_A: sản phẩm "Có sẵn" có nhiều phiên bản; SP_B: sản phẩm "Có sẵn" khác + Giỏ hàng đang trống Step: 1. Mở trang chi tiết SP_A, chọn phiên bản V1, ghi lại tên, giá 2. Click [Thêm vào giỏ hàng] 3. Click [Kiểm tra giỏ hàng] | D11: 3. Dòng sản phẩm trong giỏ có tên, phiên bản (V1), ảnh và đơn giá trùng với trang chi tiết; số lượng = 1; thành tiền = đơn giá | F11: Untested
A12: =IF(OR(B12<>"",D12<>""),"["&TEXT($B$2,"##")&"-"&TEXT(ROW()-8,"##")&"]","") -> [ShoppingCart-4] | B12: Kiểm tra thêm sản phẩm "Có sẵn" vào giỏ hàng từ trang chi tiết | C12: Pre-condition: + Dùng Chrome, truy cập https://kicap.vn, chưa đăng nhập (khách) + SP_A: sản phẩm "Có sẵn" có nhiều phiên bản; SP_B: sản phẩm "Có sẵn" khác + Giỏ hàng đang trống Step: 1. Mở trang chi tiết SP_A 2. Click [Thêm vào giỏ hàng] 3. Quan sát biểu tượng giỏ hàng ở header | D12: 2. Hiển thị popup "Thêm vào giỏ hàng thành công" với 2 nút [Tiếp tục mua hàng] và [Kiểm tra giỏ hàng] 3. Biểu tượng giỏ hàng hiển thị số lượng = 1 | F12: Untested
A13: =IF(OR(B13<>"",D13<>""),"["&TEXT($B$2,"##")&"-"&TEXT(ROW()-8,"##")&"]","") -> [ShoppingCart-5] | B13: Kiểm tra nút [Tiếp tục mua hàng] trên popup thêm vào giỏ | C13: Pre-condition: + Dùng Chrome, truy cập https://kicap.vn, chưa đăng nhập (khách) + SP_A: sản phẩm "Có sẵn" có nhiều phiên bản; SP_B: sản phẩm "Có sẵn" khác + Giỏ hàng đang trống Step: 1. Mở trang chi tiết SP_A, click [Thêm vào giỏ hàng] 2. Click [Tiếp tục mua hàng] | D13: 2. Popup đóng, người dùng vẫn ở trang chi tiết SP_A; số lượng trên biểu tượng giỏ vẫn là 1 | E13: [ShoppingCart-4] | F13: Untested
A14: =IF(OR(B14<>"",D14<>""),"["&TEXT($B$2,"##")&"-"&TEXT(ROW()-8,"##")&"]","") -> [ShoppingCart-6] | B14: Kiểm tra nút [Kiểm tra giỏ hàng] trên popup thêm vào giỏ | C14: Pre-condition: + Dùng Chrome, truy cập https://kicap.vn, chưa đăng nhập (khách) + SP_A: sản phẩm "Có sẵn" có nhiều phiên bản; SP_B: sản phẩm "Có sẵn" khác + Giỏ hàng đang trống Step: 1. Mở trang chi tiết SP_A, click [Thêm vào giỏ hàng] 2. Click [Kiểm tra giỏ hàng] | D14: 2. Chuyển đến trang /cart, hiển thị SP_A với số lượng 1 | E14: [ShoppingCart-4] | F14: Untested
A15: =IF(OR(B15<>"",D15<>""),"["&TEXT($B$2,"##")&"-"&TEXT(ROW()-8,"##")&"]","") -> [ShoppingCart-7] | B15: Kiểm tra thêm sản phẩm có nhiều phiên bản - đúng phiên bản được chọn | C15: Pre-condition: + Dùng Chrome, truy cập https://kicap.vn, chưa đăng nhập (khách) + SP_A: sản phẩm "Có sẵn" có nhiều phiên bản; SP_B: sản phẩm "Có sẵn" khác + Giỏ hàng đang trống Step: 1. Mở trang chi tiết SP_A 2. Chọn phiên bản V2 3. Click [Thêm vào giỏ hàng] 4. Click [Kiểm tra giỏ hàng] | D15: 4. Giỏ hàng có 1 dòng SP_A đúng phiên bản V2, đơn giá là giá của V2 | F15: Untested
A16: =IF(OR(B16<>"",D16<>""),"["&TEXT($B$2,"##")&"-"&TEXT(ROW()-8,"##")&"]","") -> [ShoppingCart-8] | B16: Kiểm tra thêm cùng sản phẩm, cùng phiên bản 2 lần | C16: Pre-condition: + Dùng Chrome, truy cập https://kicap.vn, chưa đăng nhập (khách) + SP_A: sản phẩm "Có sẵn" có nhiều phiên bản; SP_B: sản phẩm "Có sẵn" khác + Giỏ hàng đang trống Step: 1. Mở trang chi tiết SP_A, chọn V1, click [Thêm vào giỏ hàng] 2. Click [Tiếp tục mua hàng] 3. Click [Thêm vào giỏ hàng] lần nữa 4. Click [Kiểm tra giỏ hàng] | D16: 4. Giỏ hàng chỉ có 1 dòng SP_A - V1 với số lượng = 2 (không tách thành 2 dòng); thành tiền = 2 x đơn giá | F16: Untested
A17: =IF(OR(B17<>"",D17<>""),"["&TEXT($B$2,"##")&"-"&TEXT(ROW()-8,"##")&"]","") -> [ShoppingCart-9] | B17: Kiểm tra thêm cùng sản phẩm nhưng khác phiên bản | C17: Pre-condition: + Dùng Chrome, truy cập https://kicap.vn, chưa đăng nhập (khách) + SP_A: sản phẩm "Có sẵn" có nhiều phiên bản; SP_B: sản phẩm "Có sẵn" khác + Giỏ hàng đang trống Step: 1. Mở trang chi tiết SP_A, chọn V1, click [Thêm vào giỏ hàng] 2. Click [Tiếp tục mua hàng] 3. Chọn V2, click [Thêm vào giỏ hàng] 4. Click [Kiểm tra giỏ hàng] | D17: 4. Giỏ hàng có 2 dòng riêng: SP_A - V1 (SL 1) và SP_A - V2 (SL 1); tổng tiền = giá V1 + giá V2 | F17: Untested
A18: =IF(OR(B18<>"",D18<>""),"["&TEXT($B$2,"##")&"-"&TEXT(ROW()-8,"##")&"]","") -> [ShoppingCart-10] | B18: Kiểm tra thêm 2 sản phẩm khác nhau vào giỏ | C18: Pre-condition: + Dùng Chrome, truy cập https://kicap.vn, chưa đăng nhập (khách) + SP_A: sản phẩm "Có sẵn" có nhiều phiên bản; SP_B: sản phẩm "Có sẵn" khác + Giỏ hàng đang trống Step: 1. Thêm SP_A (V1) vào giỏ 2. Thêm SP_B vào giỏ 3. Click [Kiểm tra giỏ hàng] | D18: 3. Giỏ hàng có 2 dòng SP_A và SP_B; biểu tượng giỏ hiển thị tổng số lượng = 2; tổng tiền = tổng thành tiền của 2 dòng | F18: Untested
A19: =IF(OR(B19<>"",D19<>""),"["&TEXT($B$2,"##")&"-"&TEXT(ROW()-8,"##")&"]","") -> [ShoppingCart-11] | B19: Kiểm tra thêm sản phẩm "Hết hàng" vào giỏ | C19: Pre-condition: + Dùng Chrome, truy cập https://kicap.vn, chưa đăng nhập (khách) + SP_A: sản phẩm "Có sẵn" có nhiều phiên bản; SP_B: sản phẩm "Có sẵn" khác + Giỏ hàng đang trống Step: 1. Mở trang chi tiết SP_C (trạng thái "Hết hàng") 2. Quan sát nút mua hàng 3. Click nút mua hàng (nếu còn click được) | D19: 2. Nút [Thêm vào giỏ hàng] bị vô hiệu hóa hoặc đổi thành trạng thái hết hàng 3. Sản phẩm không được thêm vào giỏ; biểu tượng giỏ không đổi | F19: Untested | H19: Cần xác nhận hành vi thực tế của site với SP hết hàng
A20: =IF(OR(B20<>"",D20<>""),"["&TEXT($B$2,"##")&"-"&TEXT(ROW()-8,"##")&"]","") -> [ShoppingCart-12] | B20: Kiểm tra thêm sản phẩm "Pre-order" vào giỏ | C20: Pre-condition: + Dùng Chrome, truy cập https://kicap.vn, chưa đăng nhập (khách) + SP_A: sản phẩm "Có sẵn" có nhiều phiên bản; SP_B: sản phẩm "Có sẵn" khác + Giỏ hàng đang trống Step: 1. Mở trang chi tiết SP_D (trạng thái "Pre-order") 2. Click nút mua/đặt trước 3. Click [Kiểm tra giỏ hàng] | D20: 2. Hiển thị thông báo thêm thành công (hoặc nút đặt trước) 3. SP_D có trong giỏ hàng với đúng giá, số lượng 1 | F20: Untested | H20: Cần xác nhận quy trình Pre-order với đội nghiệp vụ
A21: =IF(OR(B21<>"",D21<>""),"["&TEXT($B$2,"##")&"-"&TEXT(ROW()-8,"##")&"]","") -> [ShoppingCart-13] | B21: Kiểm tra thêm sản phẩm vào giỏ khi chưa đăng nhập | C21: Pre-condition: + Dùng Chrome, truy cập https://kicap.vn, chưa đăng nhập (khách) + SP_A: sản phẩm "Có sẵn" có nhiều phiên bản; SP_B: sản phẩm "Có sẵn" khác + Giỏ hàng đang trống Step: 1. Xác nhận chưa đăng nhập (header hiển thị [Đăng nhập]) 2. Thêm SP_A vào giỏ 3. Click [Kiểm tra giỏ hàng] | D21: 2. Thêm thành công, không bị yêu cầu đăng nhập 3. Giỏ hàng hiển thị SP_A | F21: Untested
A22: =IF(OR(B22<>"",D22<>""),"["&TEXT($B$2,"##")&"-"&TEXT(ROW()-8,"##")&"]","") -> [ShoppingCart-14] | B22: Kiểm tra tăng số lượng bằng nút [+] | C22: Pre-condition: + Giỏ hàng có SP_A (V1) số lượng 1 Step: 1. Mở /cart 2. Click nút [+] của SP_A một lần 3. Click nút [+] thêm một lần | D22: 2. Số lượng = 2; thành tiền = 2 x đơn giá; tổng tiền cập nhật 3. Số lượng = 3; thành tiền = 3 x đơn giá; tổng tiền cập nhật; biểu tượng giỏ ở header cập nhật | E22: [ShoppingCart-4] | F22: Untested
A23: =IF(OR(B23<>"",D23<>""),"["&TEXT($B$2,"##")&"-"&TEXT(ROW()-8,"##")&"]","") -> [ShoppingCart-15] | B23: Kiểm tra giảm số lượng bằng nút [-] | C23: Pre-condition: + Giỏ hàng có SP_A (V1) số lượng 3 Step: 1. Mở /cart 2. Click nút [-] của SP_A một lần | D23: 2. Số lượng = 2; thành tiền = 2 x đơn giá; tổng tiền cập nhật | E23: [ShoppingCart-14] | F23: Untested
A24: =IF(OR(B24<>"",D24<>""),"["&TEXT($B$2,"##")&"-"&TEXT(ROW()-8,"##")&"]","") -> [ShoppingCart-16] | B24: Kiểm tra giảm số lượng khi đang bằng 1 | C24: Pre-condition: + Giỏ hàng có SP_A (V1) số lượng 1 Step: 1. Mở /cart 2. Click nút [-] của SP_A | D24: 2. Số lượng giữ nguyên = 1 (không xuống 0/âm) hoặc sản phẩm bị xóa khỏi giỏ theo thiết kế của site | E24: [ShoppingCart-4] | F24: Untested | H24: Cần xác nhận hành vi thực tế
A25: =IF(OR(B25<>"",D25<>""),"["&TEXT($B$2,"##")&"-"&TEXT(ROW()-8,"##")&"]","") -> [ShoppingCart-17] | B25: Kiểm tra nhập số lượng hợp lệ vào ô số lượng | C25: Pre-condition: + Giỏ hàng có SP_A (V1) số lượng 1 Step: 1. Mở /cart 2. Xóa giá trị ô số lượng, nhập 5 3. Nhấn Enter (hoặc click ra ngoài ô) | D25: 3. Số lượng = 5; thành tiền = 5 x đơn giá; tổng tiền cập nhật | E25: [ShoppingCart-4] | F25: Untested
A26: =IF(OR(B26<>"",D26<>""),"["&TEXT($B$2,"##")&"-"&TEXT(ROW()-8,"##")&"]","") -> [ShoppingCart-18] | B26: Kiểm tra nhập số lượng = 0 | C26: Pre-condition: + Giỏ hàng có SP_A (V1) số lượng 1 Step: 1. Mở /cart 2. Nhập 0 vào ô số lượng 3. Nhấn Enter | D26: 3. Số lượng không được là 0: hệ thống tự đưa về 1, hoặc xóa sản phẩm khỏi giỏ (có xác nhận); tổng tiền không bị sai | E26: [ShoppingCart-4] | F26: Untested | H26: Cần xác nhận hành vi thực tế
A27: =IF(OR(B27<>"",D27<>""),"["&TEXT($B$2,"##")&"-"&TEXT(ROW()-8,"##")&"]","") -> [ShoppingCart-19] | B27: Kiểm tra nhập số lượng âm | C27: Pre-condition: + Giỏ hàng có SP_A (V1) số lượng 1 Step: 1. Mở /cart 2. Nhập -1 vào ô số lượng 3. Nhấn Enter | D27: 3. Hệ thống không chấp nhận số âm: giữ/đưa về số lượng hợp lệ (>= 1); tổng tiền không âm | E27: [ShoppingCart-4] | F27: Untested
A28: =IF(OR(B28<>"",D28<>""),"["&TEXT($B$2,"##")&"-"&TEXT(ROW()-8,"##")&"]","") -> [ShoppingCart-20] | B28: Kiểm tra nhập ký tự chữ vào ô số lượng | C28: Pre-condition: + Giỏ hàng có SP_A (V1) số lượng 1 Step: 1. Mở /cart 2. Nhập "abc" vào ô số lượng 3. Nhấn Enter | D28: 2. Ô số lượng không nhận ký tự chữ (hoặc bị bỏ qua) 3. Số lượng giữ giá trị hợp lệ cũ = 1; không xuất hiện lỗi/trang trắng | E28: [ShoppingCart-4] | F28: Untested
A29: =IF(OR(B29<>"",D29<>""),"["&TEXT($B$2,"##")&"-"&TEXT(ROW()-8,"##")&"]","") -> [ShoppingCart-21] | B29: Kiểm tra nhập số lượng thập phân | C29: Pre-condition: + Giỏ hàng có SP_A (V1) số lượng 1 Step: 1. Mở /cart 2. Nhập 1.5 vào ô số lượng 3. Nhấn Enter | D29: 3. Hệ thống không chấp nhận số thập phân: làm tròn/giữ số nguyên hợp lệ; thành tiền tính đúng theo số nguyên | E29: [ShoppingCart-4] | F29: Untested
A30: =IF(OR(B30<>"",D30<>""),"["&TEXT($B$2,"##")&"-"&TEXT(ROW()-8,"##")&"]","") -> [ShoppingCart-22] | B30: Kiểm tra nhập số lượng lớn vượt tồn kho | C30: Pre-condition: + Giỏ hàng có SP_A (V1) số lượng 1 Step: 1. Mở /cart 2. Nhập 9999 vào ô số lượng 3. Nhấn Enter | D30: 3. Hiển thị thông báo vượt số lượng tồn kho/giới hạn, số lượng được giới hạn ở mức tối đa cho phép; không báo lỗi hệ thống | E30: [ShoppingCart-4] | F30: Untested | H30: Cần xác nhận giới hạn tồn kho thực tế
A31: =IF(OR(B31<>"",D31<>""),"["&TEXT($B$2,"##")&"-"&TEXT(ROW()-8,"##")&"]","") -> [ShoppingCart-23] | B31: Kiểm tra xóa 1 sản phẩm khỏi giỏ có nhiều sản phẩm | C31: Pre-condition: + Giỏ hàng có SP_A (V1) và SP_B Step: 1. Mở /cart 2. Click nút xóa của SP_A | D31: 2. SP_A biến mất khỏi giỏ, SP_B vẫn còn; tổng tiền = thành tiền của SP_B; biểu tượng giỏ cập nhật | E31: [ShoppingCart-10] | F31: Untested
A32: =IF(OR(B32<>"",D32<>""),"["&TEXT($B$2,"##")&"-"&TEXT(ROW()-8,"##")&"]","") -> [ShoppingCart-24] | B32: Kiểm tra xóa sản phẩm cuối cùng - giỏ hàng trống | C32: Pre-condition: + Giỏ hàng chỉ có SP_A (V1) Step: 1. Mở /cart 2. Click nút xóa của SP_A | D32: 2. Hiển thị thông báo giỏ hàng trống; biểu tượng giỏ về 0; không còn nút [Thanh toán] hoạt động | E32: [ShoppingCart-4] | F32: Untested
A33: =IF(OR(B33<>"",D33<>""),"["&TEXT($B$2,"##")&"-"&TEXT(ROW()-8,"##")&"]","") -> [ShoppingCart-25] | B33: Kiểm tra thành tiền và tổng tiền với sản phẩm đang giảm giá | C33: Pre-condition: + SP_E đang giảm giá (hiển thị giá gốc gạch ngang); SP_A giá thường Step: 1. Thêm SP_E (SL 2) và SP_A (SL 1) vào giỏ 2. Mở /cart và tính tay: tổng = 2 x giá sau giảm của SP_E + giá SP_A | D33: 2. Đơn giá dùng giá sau giảm; thành tiền từng dòng đúng; tổng tiền khớp giá trị tính tay; định dạng tiền tệ đúng (dấu phân cách, ký hiệu ₫) | E33: [ShoppingCart-10] | F33: Untested
A34: =IF(OR(B34<>"",D34<>""),"["&TEXT($B$2,"##")&"-"&TEXT(ROW()-8,"##")&"]","") -> [ShoppingCart-26] | B34: Kiểm tra giỏ hàng được giữ lại sau khi tải lại trang | C34: Pre-condition: + Giỏ hàng có SP_A (V1) số lượng 2 Step: 1. Mở /cart 2. Nhấn F5 để tải lại trang | D34: 2. Giỏ hàng vẫn giữ SP_A (V1) số lượng 2, tổng tiền không đổi | E34: [ShoppingCart-4] | F34: Untested
A35: =IF(OR(B35<>"",D35<>""),"["&TEXT($B$2,"##")&"-"&TEXT(ROW()-8,"##")&"]","") -> [ShoppingCart-27] | B35: Kiểm tra giỏ hàng được giữ lại khi mở tab mới / đóng mở lại trình duyệt | C35: Pre-condition: + Giỏ hàng có SP_A (V1) số lượng 2 Step: 1. Mở tab mới, truy cập https://kicap.vn/cart 2. Đóng toàn bộ trình duyệt, mở lại và truy cập /cart | D35: 1. Tab mới hiển thị đúng giỏ hàng (SP_A, SL 2) 2. Giỏ hàng vẫn còn (theo cookie/phiên của site) | E35: [ShoppingCart-4] | F35: Untested | H35: Cần xác nhận thời gian lưu giỏ hàng
A36: =IF(OR(B36<>"",D36<>""),"["&TEXT($B$2,"##")&"-"&TEXT(ROW()-8,"##")&"]","") -> [ShoppingCart-28] | B36: Kiểm tra số lượng ở biểu tượng giỏ hàng cập nhật đồng bộ khi thay đổi giỏ | C36: Pre-condition: + Giỏ hàng trống Step: 1. Thêm SP_A (SL 1), sau đó thêm SP_B (SL 1) 2. Mở /cart, tăng SL SP_A lên 3 3. Xóa SP_B | D36: 1. Biểu tượng giỏ: 1 rồi 2 2. Biểu tượng giỏ = 4 3. Biểu tượng giỏ = 3 | E36: [ShoppingCart-10] | F36: Untested
A37: =IF(OR(B37<>"",D37<>""),"["&TEXT($B$2,"##")&"-"&TEXT(ROW()-8,"##")&"]","") -> [ShoppingCart-29] | B37: Kiểm tra nút [Thanh toán] khi giỏ có sản phẩm | C37: Pre-condition: + Giỏ hàng có SP_A (V1) số lượng 1 Step: 1. Mở /cart 2. Click nút [Thanh toán] | D37: 2. Chuyển đến trang /checkout; thông tin sản phẩm và tổng tiền khớp với giỏ hàng | E37: [ShoppingCart-4] | F37: Untested
A38: =IF(OR(B38<>"",D38<>""),"["&TEXT($B$2,"##")&"-"&TEXT(ROW()-8,"##")&"]","") -> [ShoppingCart-30] | B38: Kiểm tra truy cập thanh toán khi giỏ hàng trống | C38: Pre-condition: + Dùng Chrome, truy cập https://kicap.vn, chưa đăng nhập (khách) + SP_A: sản phẩm "Có sẵn" có nhiều phiên bản; SP_B: sản phẩm "Có sẵn" khác + Giỏ hàng đang trống Step: 1. Truy cập trực tiếp https://kicap.vn/checkout 2. Truy cập https://kicap.vn/cart rồi tìm nút [Thanh toán] | D38: 1. Hệ thống không cho thanh toán: chuyển về /cart hoặc báo giỏ hàng trống 2. Không có nút [Thanh toán] hoạt động | E38: [ShoppingCart-1] | F38: Untested | H38: Cần xác nhận hành vi thực tế

Sheet Test Report
B1: TEST REPORT
B3: Project Name | C3: =Cover!C4 -> KICAP | E3: Creator | G3: Ho Ten (22130212)
B4: Project Code | C4: =Cover!C5 -> https://github.com/TuanHoangMinh12/Kiem_Thu_Nhom16 | E4: Reviewer/Approver
B5: Document Code | C5: =C4&"_"&"Test Report"&"_"&"v0.1" -> https://github.com/TuanHoangMinh12/Kiem_Thu_Nhom16_Test Report_v0.1 | E5: Issue Date | G5: 46318
B6: Notes | C6: Release 1 gồm 1 module: ShoppingCart (kicap.vn)
B10: No | C10: Module code | D10: Pass | E10: Fail | F10: Untested | G10: Blocked | H10: Skipped | I10: Number of test cases
B11: 1 | C11: ='Shopping Cart'!B2 -> ShoppingCart | D11: ='Shopping Cart'!A6 -> 0 | E11: ='Shopping Cart'!B6 -> 0 | F11: ='Shopping Cart'!C6 -> 30 | G11: ='Shopping Cart'!D6 -> 0 | H11: ='Shopping Cart'!E6 -> 0 | I11: ='Shopping Cart'!F6 -> 30
C15: Sub total | D15: =SUM(D9:D14) -> 0 | E15: =SUM(E9:E14) -> 0 | F15: =SUM(F9:F14) -> 30 | G15: =SUM(G9:G14) -> 0 | H15: =SUM(H9:H14) -> 0 | I15: =SUM(I9:I14) -> 30
C17: Test coverage | E17: =IF((I15-H15-G15)=0,0,(D15+E15)*100/(I15-H15-G15)) -> 0 | F17: %
C18: Test successful coverage | E18: =IF((D15+E15)=0,0,D15*100/(D15+E15)) -> 0 | F18: %

Sheet Automation Plan
B1: AUTOMATION TEST PLAN - Shopping Cart (kicap.vn)
B3: Mục tiêu | C3: Tự động hóa kiểm thử hồi quy cho chức năng Giỏ hàng; chạy nhanh sau mỗi lần cập nhật website
B4: Công cụ (đề xuất) | C4: Selenium WebDriver + Java + TestNG + Maven (hoặc Playwright); mô hình Page Object (CartPage, ProductPage, HeaderComponent)
B5: Dữ liệu test | C5: File CSV/Excel: URL sản phẩm, phiên bản, số lượng, kết quả mong đợi (data-driven)
B6: Báo cáo / CI | C6: Allure hoặc ExtentReports; GitHub Actions chạy khi push/merge vào nhánh dev
B7: Cấu trúc repo | C7: src/test/java/{pages,tests,utils} - src/test/resources/testdata - docs/GroupXX_MaSV_HoTen.xlsx
B8: Phạm vi không tự động | C8: GUI cảm quan (layout), kiểm tra tay cho Pre-order/tồn kho khi chưa có dữ liệu ổn định
B10: Quy trình (checklist)
B11: [ ] 1. Chốt phạm vi & chọn TC tự động hóa (cột Automate bên dưới)
B12: [ ] 2. Dựng project Maven/TestNG, cấu hình WebDriver, đẩy lên nhánh cá nhân
B13: [ ] 3. Viết Page Object: ProductPage, CartPage, Header
B14: [ ] 4. Viết script cho nhóm TC Priority High (add, qty, remove, total)
B15: [ ] 5. Data-driven cho nhóm nhập số lượng (qty_*)
B16: [ ] 6. Chạy thử local, sửa locator/wait, chụp ảnh khi fail
B17: [ ] 7. Tạo báo cáo (Allure/Extent), cập nhật cột Result trong file test case
B18: [ ] 8. Tạo Pull Request nhánh cá nhân -> dev, nhóm trưởng gộp tài liệu GroupXX_TenProject
B20: No | C20: Test case ID | D20: Test case | E20: Priority | F20: Automate | G20: Kỹ thuật / ghi chú
B21: 1 | C21: [ShoppingCart-1] | D21: Kiểm tra mở trang giỏ hàng khi giỏ trống bằng biểu tượng giỏ ở header | E21: High | F21: Yes
B22: 2 | C22: [ShoppingCart-2] | D22: Kiểm tra giao diện (layout) trang giỏ hàng khi có sản phẩm | E22: Low | F22: No | G22: Kiểm tra mắt/visual; có thể bổ sung chụp ảnh so sánh
B23: 3 | C23: [ShoppingCart-3] | D23: Kiểm tra thông tin sản phẩm trong giỏ khớp với trang chi tiết | E23: High | F23: Yes
B24: 4 | C24: [ShoppingCart-4] | D24: Kiểm tra thêm sản phẩm "Có sẵn" vào giỏ hàng từ trang chi tiết | E24: High | F24: Yes
B25: 5 | C25: [ShoppingCart-5] | D25: Kiểm tra nút [Tiếp tục mua hàng] trên popup thêm vào giỏ | E25: Medium | F25: Yes
B26: 6 | C26: [ShoppingCart-6] | D26: Kiểm tra nút [Kiểm tra giỏ hàng] trên popup thêm vào giỏ | E26: Medium | F26: Yes
B27: 7 | C27: [ShoppingCart-7] | D27: Kiểm tra thêm sản phẩm có nhiều phiên bản - đúng phiên bản được chọn | E27: High | F27: Yes
B28: 8 | C28: [ShoppingCart-8] | D28: Kiểm tra thêm cùng sản phẩm, cùng phiên bản 2 lần | E28: High | F28: Yes
B29: 9 | C29: [ShoppingCart-9] | D29: Kiểm tra thêm cùng sản phẩm nhưng khác phiên bản | E29: High | F29: Yes
B30: 10 | C30: [ShoppingCart-10] | D30: Kiểm tra thêm 2 sản phẩm khác nhau vào giỏ | E30: High | F30: Yes
B31: 11 | C31: [ShoppingCart-11] | D31: Kiểm tra thêm sản phẩm "Hết hàng" vào giỏ | E31: Medium | F31: Partial | G31: Cần SP hết hàng ổn định
B32: 12 | C32: [ShoppingCart-12] | D32: Kiểm tra thêm sản phẩm "Pre-order" vào giỏ | E32: Low | F32: No | G32: Quy trình Pre-order chưa rõ
B33: 13 | C33: [ShoppingCart-13] | D33: Kiểm tra thêm sản phẩm vào giỏ khi chưa đăng nhập | E33: High | F33: Yes
B34: 14 | C34: [ShoppingCart-14] | D34: Kiểm tra tăng số lượng bằng nút [+] | E34: High | F34: Yes | G34: Data-driven (TestNG DataProvider)
B35: 15 | C35: [ShoppingCart-15] | D35: Kiểm tra giảm số lượng bằng nút [-] | E35: High | F35: Yes | G35: Data-driven (TestNG DataProvider)
B36: 16 | C36: [ShoppingCart-16] | D36: Kiểm tra giảm số lượng khi đang bằng 1 | E36: High | F36: Yes | G36: Data-driven (TestNG DataProvider)
B37: 17 | C37: [ShoppingCart-17] | D37: Kiểm tra nhập số lượng hợp lệ vào ô số lượng | E37: High | F37: Yes | G37: Data-driven (TestNG DataProvider)
B38: 18 | C38: [ShoppingCart-18] | D38: Kiểm tra nhập số lượng = 0 | E38: High | F38: Yes | G38: Data-driven (TestNG DataProvider)
B39: 19 | C39: [ShoppingCart-19] | D39: Kiểm tra nhập số lượng âm | E39: High | F39: Yes | G39: Data-driven (TestNG DataProvider)
B40: 20 | C40: [ShoppingCart-20] | D40: Kiểm tra nhập ký tự chữ vào ô số lượng | E40: High | F40: Yes | G40: Data-driven (TestNG DataProvider)
B41: 21 | C41: [ShoppingCart-21] | D41: Kiểm tra nhập số lượng thập phân | E41: High | F41: Yes | G41: Data-driven (TestNG DataProvider)
B42: 22 | C42: [ShoppingCart-22] | D42: Kiểm tra nhập số lượng lớn vượt tồn kho | E42: Medium | F42: Partial | G42: Phụ thuộc tồn kho
B43: 23 | C43: [ShoppingCart-23] | D43: Kiểm tra xóa 1 sản phẩm khỏi giỏ có nhiều sản phẩm | E43: High | F43: Yes
...
